Workbook
Name BinDivisor: 'Overall Metrics'!$X$2
Name DynamicFilterColumnName: 'Overall Metrics'!#REF!
Name DynamicFilterForceCalculationRange: HistogramBins[[Dynamic Filter Bin]:[Dynamic Filter Frequency]]
Name DynamicFilterSourceColumnRange: 'Overall Metrics'!$X$4
Name DynamicFilterTableName: 'Overall Metrics'!#REF!
Name NoMetricMessage: 'Overall Metrics'!$X$3
Name NotAvailable: 'Overall Metrics'!$X$2
Name ValidBooleansDefaultFalse: Misc!$G$2:$G$5
Name ValidEdgeStyles: Misc!$B$2:$B$11
Name ValidEdgeVisibilities: Misc!$A$2:$A$7
Name ValidGroupShapes: Misc!$E$2:$E$19
Name ValidGroupVisibilities: Misc!$F$2:$F$7
Name ValidVertexLabelPositions: Misc!$H$2:$H$21
Name ValidVertexShapes: Misc!$D$2:$D$23
Name ValidVertexVisibilities: Misc!$C$2:$C$9

Sheet Edges
C1: Visual Properties | H1: Labels | K1: Graph Metrics | L1: Do Not Edit | N1: Other Columns
A2: Vertex 1 | B2: Vertex 2 | C2: Color | D2: Width | E2: Style | F2: Opacity | G2: Visibility | H2: Label | I2: Label Text Color | J2: Label Font Size | K2: Reciprocated? | L2: ID | M2: Dynamic Filter | N2: Add Your Own Columns Here | O2: Relationship | P2: Relationship Date (UTC) | Q2: Tweet | R2: URLs in Tweet | S2: Domains in Tweet | T2: Hashtags in Tweet | U2: Tweet Date (UTC) | V2: Twitter Page for Tweet | W2: Latitude | X2: Longitude | Y2: Imported ID | Z2: In-Reply-To Tweet ID
A3: maxsmithtweet | B3: tesco | K3: No | L3: 3 | M3: =IF(AND(OR(NOT(ISNUMBER(Edges[Relationship Date (UTC)])), Edges[Relationship Date (UTC)] >= Misc!$O$2), OR(NOT(ISNUMBER(Edges[Relationship Date (UTC)])), Edges[Relationship Date (UTC)] <= Misc!$P$2),OR(NOT(ISNUMBER(Edges[Tweet Date (UTC)])), Edges[Tweet Date (UTC)] >= Misc!$O$3), OR(NOT(ISNUMBER(Edges[Tweet Date (UTC)])), Edges[Tweet Date (UTC)] <= Misc!$P$3),TRUE), TRUE, FALSE) -> TRUE | O3: Mentions | P3: 43045.409 | Q3: RT @Tesco: The definitive WWII campaign at an unbeatable price. Get #CODWWII for £44 at Tesco now, in-store and online. https://t.co/yEgyxR… | T3: codwwii | U3: 43045.409 | V3: https://twitter.com/#!/maxsmithtweet/status/927472778378399744 | Y3: 927472778378399744
A4: xpoze_aqua | B4: codww2intel | K4: No | L4: 4 | M4: =IF(AND(OR(NOT(ISNUMBER(Edges[Relationship Date (UTC)])), Edges[Relationship Date (UTC)] >= Misc!$O$2), OR(NOT(ISNUMBER(Edges[Relationship Date (UTC)])), Edges[Relationship Date (UTC)] <= Misc!$P$2),OR(NOT(ISNUMBER(Edges[Tweet Date (UTC)])), Edges[Tweet Date (UTC)] >= Misc!$O$3), OR(NOT(ISNUMBER(Edges[Tweet Date (UTC)])), Edges[Tweet Date (UTC)] <= Misc!$P$3),TRUE), TRUE, FALSE) -> TRUE | O4: Mentions | P4: 43045.409 | Q4: RT @CoDWW2Intel: Here's all of the 10 Prestige + Prestige Master Icons in CoD WWII! #CoDWW2 #CoDWWII Credit: Reddit (LackingAGoodName) htt… | T4: codww2 codwwii | U4: 43045.409 | V4: https://twitter.com/#!/xpoze_aqua/status/927472791607226369 | Y4: 927472791607226369
A5: infused_vanq | B5: astrogaminguk | K5: No | L5: 5 | M5: =IF(AND(OR(NOT(ISNUMBER(Edges[Relationship Date (UTC)])), Edges[Relationship Date (UTC)] >= Misc!$O$2), OR(NOT(ISNUMBER(Edges[Relationship Date (UTC)])), Edges[Relationship Date (UTC)] <= Misc!$P$2),OR(NOT(ISNUMBER(Edges[Tweet Date (UTC)])), Edges[Tweet Date (UTC)] >= Misc!$O$3), OR(NOT(ISNUMBER(Edges[Tweet Date (UTC)])), Edges[Tweet Date (UTC)] <= Misc!$P$3),TRUE), TRUE, FALSE) -> TRUE | O5: Mentions | P5: 43045.409 | Q5: RT @ASTROGamingUK: The first Monday after #CODWWII and the workforce is on the move! #ASTROfamily https://t.co/FTfIdTpNRF | T5: codwwii astrofamily | U5: 43045.409 | V5: https://twitter.com/#!/infused_vanq/status/927472805347823616 | Y5: 927472805347823616
A6: loperosal | B6: thegrefgyt | K6: No | L6: 6 | M6: =IF(AND(OR(NOT(ISNUMBER(Edges[Relationship Date (UTC)])), Edges[Relationship Date (UTC)] >= Misc!$O$2), OR(NOT(ISNUMBER(Edges[Relationship Date (UTC)])), Edges[Relationship Date (UTC)] <= Misc!$P$2),OR(NOT(ISNUMBER(Edges[Tweet Date (UTC)])), Edges[Tweet Date (UTC)] >= Misc!$O$3), OR(NOT(ISNUMBER(Edges[Tweet Date (UTC)])), Edges[Tweet Date (UTC)] <= Misc!$P$3),TRUE), TRUE, FALSE) -> TRUE | O6: Mentions | P6: 43045.409 | Q6: RT @TheGrefgYT: ¡NUEVO VÍDEO! 😡😠 #CODWWII ME BANEA 😠😡 RT Chicos!! 🙌🏻🔥▶️ https://t.co/78KdJQv8Ij https://t.co/heBObzc6N5 | R6: https://www.youtube.com/watch?v=-W5I1VoVWiI&feature=youtu.be | S6: youtube.com | T6: codwwii | U6: 43045.409 | V6: https://twitter.com/#!/loperosal/status/927472817385365504 | Y6: 927472817385365504
A7: onany_yarou | B7: onany_yarou | K7: No | L7: 7 | M7: =IF(AND(OR(NOT(ISNUMBER(Edges[Relationship Date (UTC)])), Edges[Relationship Date (UTC)] >= Misc!$O$2), OR(NOT(ISNUMBER(Edges[Relationship Date (UTC)])), Edges[Relationship Date (UTC)] <= Misc!$P$2),OR(NOT(ISNUMBER(Edges[Tweet Date (UTC)])), Edges[Tweet Date (UTC)] >= Misc!$O$3), OR(NOT(ISNUMBER(Edges[Tweet Date (UTC)])), Edges[Tweet Date (UTC)] <= Misc!$P$3),TRUE), TRUE, FALSE) -> TRUE | O7: Tweet | P7: 43045.409 | Q7: codwwⅡを買いました笑 | U7: 43045.409 | V7: https://twitter.com/#!/onany_yarou/status/927472822477135874 | Y7: 927472822477135874
A8: tweetmeista | B8: tweetmeista | K8: No | L8: 8 | M8: =IF(AND(OR(NOT(ISNUMBER(Edges[Relationship Date (UTC)])), Edges[Relationship Date (UTC)] >= Misc!$O$2), OR(NOT(ISNUMBER(Edges[Relationship Date (UTC)])), Edges[Relationship Date (UTC)] <= Misc!$P$2),OR(NOT(ISNUMBER(Edges[Tweet Date (UTC)])), Edges[Tweet Date (UTC)] >= Misc!$O$3), OR(NOT(ISNUMBER(Edges[Tweet Date (UTC)])), Edges[Tweet Date (UTC)] <= Misc!$P$3),TRUE), TRUE, FALSE) -> TRUE | O8: Tweet | P8: 43045.409 | Q8: #activision #CODWWII How can I actually log a support case?All your website does is offer solutions that don’t apply.Why is it so difficult? | T8: activision codwwii | U8: 43045.409 | V8: https://twitter.com/#!/tweetmeista/status/927472825014849537 | Y8: 927472825014849537
A9: gooya_58p | B9: decksplash | K9: No | L9: 9 | M9: =IF(AND(OR(NOT(ISNUMBER(Edges[Relationship Date (UTC)])), Edges[Relationship Date (UTC)] >= Misc!$O$2), OR(NOT(ISNUMBER(Edges[Relationship Date (UTC)])), Edges[Relationship Date (UTC)] <= Misc!$P$2),OR(NOT(ISNUMBER(Edges[Tweet Date (UTC)])), Edges[Tweet Date (UTC)] >= Misc!$O$3), OR(NOT(ISNUMBER(Edges[Tweet Date (UTC)])), Edges[Tweet Date (UTC)] <= Misc!$P$3),TRUE), TRUE, FALSE) -> TRUE | O9: Mentions | P9: 43045.409 | Q9: RT @Decksplash: Ask your mom for money to play COD... ORRRR play Decksplash RIGHT NOW for FREE! #CODWWII #Decksplash https://t.co/PUmMqBTPc… | T9: codwwii decksplash | U9: 43045.409 | V9: https://twitter.com/#!/gooya_58p/status/927472863119945728 | Y9: 927472863119945728
A10: 5xe49shsufp8w4i | B10: arabiagtx | K10: No | L10: 10 | M10: =IF(AND(OR(NOT(ISNUMBER(Edges[Relationship Date (UTC)])), Edges[Relationship Date (UTC)] >= Misc!$O$2), OR(NOT(ISNUMBER(Edges[Relationship Date (UTC)])), Edges[Relationship Date (UTC)] <= Misc!$P$2),OR(NOT(ISNUMBER(Edges[Tweet Date (UTC)])), Edges[Tweet Date (UTC)] >= Misc!$O$3), OR(NOT(ISNUMBER(Edges[Tweet Date (UTC)])), Edges[Tweet Date (UTC)] <= Misc!$P$3),TRUE), TRUE, FALSE) -> TRUE | O10: Mentions | P10: 43045.409 | Q10: RT @ArabiaGtx: هدية للمتابعين نسخة Duluxe من #CODWWII لـXB1 أو PS4 او 100 دولار ستور: الشروط: - متابع الحساب - رتويت للتغريدة - منشن أصدقا… | T10: codwwii | U10: 43045.409 | V10: https://twitter.com/#!/5xe49shsufp8w4i/status/927472863241744384 | Y10: 927472863241744384
A11: bwdgalaxy3000 | B11: eaa_tw | K11: No | L11: 11 | M11: =IF(AND(OR(NOT(ISNUMBER(Edges[Relationship Date (UTC)])), Edges[Relationship Date (UTC)] >= Misc!$O$2), OR(NOT(ISNUMBER(Edges[Relationship Date (UTC)])), Edges[Relationship Date (UTC)] <= Misc!$P$2),OR(NOT(ISNUMBER(Edges[Tweet Date (UTC)])), Edges[Tweet Date (UTC)] >= Misc!$O$3), OR(NOT(ISNUMBER(Edges[Tweet Date (UTC)])), Edges[Tweet Date (UTC)] <= Misc!$P$3),TRUE), TRUE, FALSE) -> TRUE | O11: Mentions | P11: 43045.409 | Q11: RT @EAA_tw: CoD:WWII：サーバーの接続問題や巻き戻し現象を修正！ 原因は予想以上の人気によるアクセス集中 #CoDWWII https://t.co/iMtnw5W2Tl https://t.co/VQkd1m6D3S | R11: http://fpsjp.net/archives/294374 | S11: fpsjp.net | T11: codwwii | U11: 43045.409 | V11: https://twitter.com/#!/bwdgalaxy3000/status/927472877040943105 | Y11: 927472877040943105
A12: sakana3385 | B12: sakana3385 | K12: No | L12: 12 | M12: =IF(AND(OR(NOT(ISNUMBER(Edges[Relationship Date (UTC)])), Edges[Relationship Date (UTC)] >= Misc!$O$2), OR(NOT(ISNUMBER(Edges[Relationship Date (UTC)])), Edges[Relationship Date (UTC)] <= Misc!$P$2),OR(NOT(ISNUMBER(Edges[Tweet Date (UTC)])), Edges[Tweet Date (UTC)] >= Misc!$O$3), OR(NOT(ISNUMBER(Edges[Tweet Date (UTC)])), Edges[Tweet Date (UTC)] <= Misc!$P$3),TRUE), TRUE, FALSE) -> TRUE | O12: Tweet | P12: 43045.409 | Q12: https://t.co/dC9A3bfFAe うぐっ | R12: https://www.jp.playstation.com/blog/detail/5914/20171030-codwwii.html | S12: playstation.com | U12: 43045.409 | V12: https://twitter.com/#!/sakana3385/status/927472920967856128 | Y12: 927472920967856128 | Z12: 927384214609080320
A13: tonytony_555 | B13: eaa_tw | K13: No | L13: 13 | M13: =IF(AND(OR(NOT(ISNUMBER(Edges[Relationship Date (UTC)])), Edges[Relationship Date (UTC)] >= Misc!$O$2), OR(NOT(ISNUMBER(Edges[Relationship Date (UTC)])), Edges[Relationship Date (UTC)] <= Misc!$P$2),OR(NOT(ISNUMBER(Edges[Tweet Date (UTC)])), Edges[Tweet Date (UTC)] >= Misc!$O$3), OR(NOT(ISNUMBER(Edges[Tweet Date (UTC)])), Edges[Tweet Date (UTC)] <= Misc!$P$3),TRUE), TRUE, FALSE) -> TRUE | O13: Mentions | P13: 43045.409 | Q13: RT @EAA_tw: CoD:WWII： プレステージアイコン全10種と、プレステージマスターアイコンが判明 #CoDWWII https://t.co/PSkNgKtZ3K https://t.co/41SmfDFFhy | R13: http://fpsjp.net/archives/294392 | S13: fpsjp.net | T13: codwwii | U13: 43045.409 | V13: https://twitter.com/#!/tonytony_555/status/927472949321281537 | Y13: 927472949321281537
A14: tanakan_1st | B14: eaa_tw | K14: No | L14: 14 | M14: =IF(AND(OR(NOT(ISNUMBER(Edges[Relationship Date (UTC)])), Edges[Relationship Date (UTC)] >= Misc!$O$2), OR(NOT(ISNUMBER(Edges[Relationship Date (UTC)])), Edges[Relationship Date (UTC)] <= Misc!$P$2),OR(NOT(ISNUMBER(Edges[Tweet Date (UTC)])), Edges[Tweet Date (UTC)] >= Misc!$O$3), OR(NOT(ISNUMBER(Edges[Tweet Date (UTC)])), Edges[Tweet Date (UTC)] <= Misc!$P$3),TRUE), TRUE, FALSE) -> TRUE | O14: Mentions | P14: 43045.409 | Q14: RT @EAA_tw: CoD:WWII：サーバーの接続問題や巻き戻し現象を修正！ 原因は予想以上の人気によるアクセス集中 #CoDWWII https://t.co/iMtnw5W2Tl https://t.co/VQkd1m6D3S | R14: http://fpsjp.net/archives/294374 | S14: fpsjp.net | T14: codwwii | U14: 43045.409 | V14: https://twitter.com/#!/tanakan_1st/status/927472959702286337 | Y14: 927472959702286337
A15: munchkinletty | B15: munchkinletty | K15: No | L15: 15 | M15: =IF(AND(OR(NOT(ISNUMBER(Edges[Relationship Date (UTC)])), Edges[Relationship Date (UTC)] >= Misc!$O$2), OR(NOT(ISNUMBER(Edges[Relationship Date (UTC)])), Edges[Relationship Date (UTC)] <= Misc!$P$2),OR(NOT(ISNUMBER(Edges[Tweet Date (UTC)])), Edges[Tweet Date (UTC)] >= Misc!$O$3), OR(NOT(ISNUMBER(Edges[Tweet Date (UTC)])), Edges[Tweet Date (UTC)] <= Misc!$P$3),TRUE), TRUE, FALSE) -> TRUE | O15: Tweet | P15: 43045.409 | Q15: Me to myself: "Ima go to sleep after this match" Also me: *starts another match* 😴 #CODWWII #gaming | T15: codwwii gaming | U15: 43045.409 | V15: https://twitter.com/#!/munchkinletty/status/927472759420022784 | Y15: 927472759420022784
A16: johnstezer | B16: munchkinletty | K16: No | L16: 16 | M16: =IF(AND(OR(NOT(ISNUMBER(Edges[Relationship Date (UTC)])), Edges[Relationship Date (UTC)] >= Misc!$O$2), OR(NOT(ISNUMBER(Edges[Relationship Date (UTC)])), Edges[Relationship Date (UTC)] <= Misc!$P$2),OR(NOT(ISNUMBER(Edges[Tweet Date (UTC)])), Edges[Tweet Date (UTC)] >= Misc!$O$3), OR(NOT(ISNUMBER(Edges[Tweet Date (UTC)])), Edges[Tweet Date (UTC)] <= Misc!$P$3),TRUE), TRUE, FALSE) -> TRUE | O16: Mentions | P16: 43045.409 | Q16: RT @MunchkinLetty: Me to myself: "Ima go to sleep after this match" Also me: *starts another match* 😴 #CODWWII #gaming | T16: codwwii gaming | U16: 43045.409 | V16: https://twitter.com/#!/johnstezer/status/927472960973295617 | Y16: 927472960973295617
A17: quent48911092 | B17: game_collection | K17: No | L17: 17 | M17: =IF(AND(OR(NOT(ISNUMBER(Edges[Relationship Date (UTC)])), Edges[Relationship Date (UTC)] >= Misc!$O$2), OR(NOT(ISNUMBER(Edges[Relationship Date (UTC)])), Edges[Relationship Date (UTC)] <= Misc!$P$2),OR(NOT(ISNUMBER(Edges[Tweet Date (UTC)])), Edges[Tweet Date (UTC)] >= Misc!$O$3), OR(NOT(ISNUMBER(Edges[Tweet Date (UTC)])), Edges[Tweet Date (UTC)] <= Misc!$P$3),TRUE), TRUE, FALSE) -> TRUE | O17: Mentions | P17: 43045.409 | Q17: Win #CODWWII on #PS4 or #XboxOne! RT + Follow @postabargain &amp; @game_collection and enter here: https://t.co/euTqBOogfK | R17: https://gleam.io/oyimv-nqfxU4?l=http%3A%2F%2Fwww.postabargain.co.uk%2Fpages%2Fcompetition%2F2017%2Fcall-of-duty-wwii-giveaway | S17: gleam.io | T17: codwwii ps4 xboxone | U17: 43045.409 | V17: https://twitter.com/#!/quent48911092/status/927472920607186944 | Y17: 927472920607186944
A18: quent48911092 | B18: postabargain | K18: No | L18: 18 | M18: =IF(AND(OR(NOT(ISNUMBER(Edges[Relationship Date (UTC)])), Edges[Relationship Date (UTC)] >= Misc!$O$2), OR(NOT(ISNUMBER(Edges[Relationship Date (UTC)])), Edges[Relationship Date (UTC)] <= Misc!$P$2),OR(NOT(ISNUMBER(Edges[Tweet Date (UTC)])), Edges[Tweet Date (UTC)] >= Misc!$O$3), OR(NOT(ISNUMBER(Edges[Tweet Date (UTC)])), Edges[Tweet Date (UTC)] <= Misc!$P$3),TRUE), TRUE, FALSE) -> TRUE | O18: Mentions | P18: 43045.409 | Q18: Win #CODWWII on #PS4 or #XboxOne! RT + Follow @postabargain &amp; @game_collection and enter here: https://t.co/euTqBOogfK | R18: https://gleam.io/oyimv-nqfxU4?l=http%3A%2F%2Fwww.postabargain.co.uk%2Fpages%2Fcompetition%2F2017%2Fcall-of-duty-wwii-giveaway | S18: gleam.io | T18: codwwii ps4 xboxone | U18: 43045.409 | V18: https://twitter.com/#!/quent48911092/status/927472920607186944 | Y18: 927472920607186944
A19: quent48911092 | B19: game_collection | K19: No | L19: 19 | M19: =IF(AND(OR(NOT(ISNUMBER(Edges[Relationship Date (UTC)])), Edges[Relationship Date (UTC)] >= Misc!$O$2), OR(NOT(ISNUMBER(Edges[Relationship Date (UTC)])), Edges[Relationship Date (UTC)] <= Misc!$P$2),OR(NOT(ISNUMBER(Edges[Tweet Date (UTC)])), Edges[Tweet Date (UTC)] >= Misc!$O$3), OR(NOT(ISNUMBER(Edges[Tweet Date (UTC)])), Edges[Tweet Date (UTC)] <= Misc!$P$3),TRUE), TRUE, FALSE) -> TRUE | O19: Mentions | P19: 43045.409 | Q19: Enter &amp; help me win this Call of Duty WWII competition by @postabargain &amp; @game_collection #CODWWII https://t.co/euTqBOFREk | R19: https://gleam.io/oyimv-nqfxU4?l=http%3A%2F%2Fwww.postabargain.co.uk%2Fpages%2Fcompetition%2F2017%2Fcall-of-duty-wwii-giveaway | S19: gleam.io | T19: codwwii | U19: 43045.409 | V19: https://twitter.com/#!/quent48911092/status/927472982364246016 | Y19: 927472982364246016
A20: quent48911092 | B20: postabargain | K20: No | L20: 20 | M20: =IF(AND(OR(NOT(ISNUMBER(Edges[Relationship Date (UTC)])), Edges[Relationship Date (UTC)] >= Misc!$O$2), OR(NOT(ISNUMBER(Edges[Relationship Date (UTC)])), Edges[Relationship Date (UTC)] <= Misc!$P$2),OR(NOT(ISNUMBER(Edges[Tweet Date (UTC)])), Edges[Tweet Date (UTC)] >= Misc!$O$3), OR(NOT(ISNUMBER(Edges[Tweet Date (UTC)])), Edges[Tweet Date (UTC)] <= Misc!$P$3),TRUE), TRUE, FALSE) -> TRUE | O20: Mentions | P20: 43045.409 | Q20: Enter &amp; help me win this Call of Duty WWII competition by @postabargain &amp; @game_collection #CODWWII https://t.co/euTqBOFREk | R20: https://gleam.io/oyimv-nqfxU4?l=http%3A%2F%2Fwww.postabargain.co.uk%2Fpages%2Fcompetition%2F2017%2Fcall-of-duty-wwii-giveaway | S20: gleam.io | T20: codwwii | U20: 43045.409 | V20: https://twitter.com/#!/quent48911092/status/927472982364246016 | Y20: 927472982364246016
A21: 10veax | B21: apex_clan1 | K21: No | L21: 21 | M21: =IF(AND(OR(NOT(ISNUMBER(Edges[Relationship Date (UTC)])), Edges[Relationship Date (UTC)] >= Misc!$O$2), OR(NOT(ISNUMBER(Edges[Relationship Date (UTC)])), Edges[Relationship Date (UTC)] <= Misc!$P$2),OR(NOT(ISNUMBER(Edges[Tweet Date (UTC)])), Edges[Tweet Date (UTC)] >= Misc!$O$3), OR(NOT(ISNUMBER(Edges[Tweet Date (UTC)])), Edges[Tweet Date (UTC)] <= Misc!$P$3),TRUE), TRUE, FALSE) -> TRUE | O21: Mentions | P21: 43045.409 | Q21: RT @ApeX_Clan1: Une des maps trouvés dans les fichiers de #CODWWII pour le DLC 1... #RT si tu l'as reconnu 👀 https://t.co/Q3BJmgQAOZ | T21: codwwii rt | U21: 43045.409 | V21: https://twitter.com/#!/10veax/status/927473028040183808 | Y21: 927473028040183808
A22: regen2206 | B22: decksplash | K22: No | L22: 22 | M22: =IF(AND(OR(NOT(ISNUMBER(Edges[Relationship Date (UTC)])), Edges[Relationship Date (UTC)] >= Misc!$O$2), OR(NOT(ISNUMBER(Edges[Relationship Date (UTC)])), Edges[Relationship Date (UTC)] <= Misc!$P$2),OR(NOT(ISNUMBER(Edges[Tweet Date (UTC)])), Edges[Tweet Date (UTC)] >= Misc!$O$3), OR(NOT(ISNUMBER(Edges[Tweet Date (UTC)])), Edges[Tweet Date (UTC)] <= Misc!$P$3),TRUE), TRUE, FALSE) -> TRUE | O22: Mentions | P22: 43045.409 | Q22: RT @Decksplash: Ask your mom for money to play COD... ORRRR play Decksplash RIGHT NOW for FREE! #CODWWII #Decksplash https://t.co/PUmMqBTPc… | T22: codwwii decksplash | U22: 43045.409 | V22: https://twitter.com/#!/regen2206/status/927473029256396800 | Y22: 927473029256396800
A23: gibelloscar | B23: jinhix | K23: No | L23: 23 | M23: =IF(AND(OR(NOT(ISNUMBER(Edges[Relationship Date (UTC)])), Edges[Relationship Date (UTC)] >= Misc!$O$2), OR(NOT(ISNUMBER(Edges[Relationship Date (UTC)])), Edges[Relationship Date (UTC)] <= Misc!$P$2),OR(NOT(ISNUMBER(Edges[Tweet Date (UTC)])), Edges[Tweet Date (UTC)] >= Misc!$O$3), OR(NOT(ISNUMBER(Edges[Tweet Date (UTC)])), Edges[Tweet Date (UTC)] <= Misc!$P$3),TRUE), TRUE, FALSE) -> TRUE | O23: Mentions | P23: 43045.409 | Q23: RT @jinhix: Mañana libro chic@s, si veo mucho apoyo en este tweet hoy me compro el #CODWWII y entre hoy y mañana me hago unos directos con… | T23: codwwii | U23: 43045.409 | V23: https://twitter.com/#!/gibelloscar/status/927473036172955649 | Y23: 927473036172955649
A24: joeypescione | B24: codww2intel | K24: No | L24: 24 | M24: =IF(AND(OR(NOT(ISNUMBER(Edges[Relationship Date (UTC)])), Edges[Relationship Date (UTC)] >= Misc!$O$2), OR(NOT(ISNUMBER(Edges[Relationship Date (UTC)])), Edges[Relationship Date (UTC)] <= Misc!$P$2),OR(NOT(ISNUMBER(Edges[Tweet Date (UTC)])), Edges[Tweet Date (UTC)] >= Misc!$O$3), OR(NOT(ISNUMBER(Edges[Tweet Date (UTC)])), Edges[Tweet Date (UTC)] <= Misc!$P$3),TRUE), TRUE, FALSE) -> TRUE | O24: Mentions | P24: 43045.41 | Q24: RT @CoDWW2Intel: RT if you agree the Snipers and BAR need nerfing in #CoDWWII What else do you feel needs changing? | T24: codwwii | U24: 43045.41 | V24: https://twitter.com/#!/joeypescione/status/927473076312399872 | Y24: 927473076312399872
A25: usmaan_ali | B25: michaelcondrey | K25: No | L25: 25 | M25: =IF(AND(OR(NOT(ISNUMBER(Edges[Relationship Date (UTC)])), Edges[Relationship Date (UTC)] >= Misc!$O$2), OR(NOT(ISNUMBER(Edges[Relationship Date (UTC)])), Edges[Relationship Date (UTC)] <= Misc!$P$2),OR(NOT(ISNUMBER(Edges[Tweet Date (UTC)])), Edges[Tweet Date (UTC)] >= Misc!$O$3), OR(NOT(ISNUMBER(Edges[Tweet Date (UTC)])), Edges[Tweet Date (UTC)] <= Misc!$P$3),TRUE), TRUE, FALSE) -> TRUE | O25: Mentions | P25: 43045.41 | Q25: RT @FaZeJev: @MichaelCondrey Hey is there a Dark Matter/Exclusion Zone equivalent in CODWWII? I need to know if contemplating throwing myse… | U25: 43045.41 | V25: https://twitter.com/#!/usmaan_ali/status/927473186287112192 | Y25: 927473186287112192
A26: usmaan_ali | B26: fazejev | K26: No | L26: 26 | M26: =IF(AND(OR(NOT(ISNUMBER(Edges[Relationship Date (UTC)])), Edges[Relationship Date (UTC)] >= Misc!$O$2), OR(NOT(ISNUMBER(Edges[Relationship Date (UTC)])), Edges[Relationship Date (UTC)] <= Misc!$P$2),OR(NOT(ISNUMBER(Edges[Tweet Date (UTC)])), Edges[Tweet Date (UTC)] >= Misc!$O$3), OR(NOT(ISNUMBER(Edges[Tweet Date (UTC)])), Edges[Tweet Date (UTC)] <= Misc!$P$3),TRUE), TRUE, FALSE) -> TRUE | O26: Mentions | P26: 43045.41 | Q26: RT @FaZeJev: @MichaelCondrey Hey is there a Dark Matter/Exclusion Zone equivalent in CODWWII? I need to know if contemplating throwing myse… | U26: 43045.41 | V26: https://twitter.com/#!/usmaan_ali/status/927473186287112192 | Y26: 927473186287112192
A27: acesxmet | B27: vweazzy | K27: No | L27: 27 | M27: =IF(AND(OR(NOT(ISNUMBER(Edges[Relationship Date (UTC)])), Edges[Relationship Date (UTC)] >= Misc!$O$2), OR(NOT(ISNUMBER(Edges[Relationship Date (UTC)])), Edges[Relationship Date (UTC)] <= Misc!$P$2),OR(NOT(ISNUMBER(Edges[Tweet Date (UTC)])), Edges[Tweet Date (UTC)] >= Misc!$O$3), OR(NOT(ISNUMBER(Edges[Tweet Date (UTC)])), Edges[Tweet Date (UTC)] <= Misc!$P$3),TRUE), TRUE, FALSE) -> TRUE | O27: Mentions | P27: 43045.41 | Q27: RT @VWeazzy: Jemand hier der richtig sicke Embleme ingame macht #CODWWII? wenns sick ist, lass ich was springen👌🏻😝 | T27: codwwii | U27: 43045.41 | V27: https://twitter.com/#!/acesxmet/status/927473273125957633 | Y27: 927473273125957633
A28: kuromamonism | B28: rushgamingjp | K28: No | L28: 28 | M28: =IF(AND(OR(NOT(ISNUMBER(Edges[Relationship Date (UTC)])), Edges[Relationship Date (UTC)] >= Misc!$O$2), OR(NOT(ISNUMBER(Edges[Relationship Date (UTC)])), Edges[Relationship Date (UTC)] <= Misc!$P$2),OR(NOT(ISNUMBER(Edges[Tweet Date (UTC)])), Edges[Tweet Date (UTC)] >= Misc!$O$3), OR(NOT(ISNUMBER(Edges[Tweet Date (UTC)])), Edges[Tweet Date (UTC)] <= Misc!$P$3),TRUE), TRUE, FALSE) -> TRUE | O28: Mentions | P28: 43045.41 | Q28: RT @RushGamingJP: 【Rush Gaming発足記念キャンペーン！】 @RushGamingJPをフォロー＆このツイートをRTで、プロチームご用達公式コントローラー、「Scuf Impact 」を抽選で1名様にプレゼント! 応募期限：11/30 23:59 #r… | U28: 43045.41 | V28: https://twitter.com/#!/kuromamonism/status/927473311411453952 | Y28: 927473311411453952
A29: frankiethetell | B29: vatoisloco | K29: No | L29: 29 | M29: =IF(AND(OR(NOT(ISNUMBER(Edges[Relationship Date (UTC)])), Edges[Relationship Date (UTC)] >= Misc!$O$2), OR(NOT(ISNUMBER(Edges[Relationship Date (UTC)])), Edges[Relationship Date (UTC)] <= Misc!$P$2),OR(NOT(ISNUMBER(Edges[Tweet Date (UTC)])), Edges[Tweet Date (UTC)] >= Misc!$O$3), OR(NOT(ISNUMBER(Edges[Tweet Date (UTC)])), Edges[Tweet Date (UTC)] <= Misc!$P$3),TRUE), TRUE, FALSE) -> TRUE | O29: Mentions | P29: 43045.41 | Q29: RT @VatoIsLoco: How Does My #Mexican #Flag #CODWWII Emblem Look Took About 1hr But I'm Liking It #PS4 https://t.co/Fb9HMNZJVa | T29: mexican flag codwwii ps4 | U29: 43045.41 | V29: https://twitter.com/#!/frankiethetell/status/927473381154234368 | Y29: 927473381154234368
A30: gouki21451224 | B30: playstation_jp | K30: No | L30: 30 | M30: =IF(AND(OR(NOT(ISNUMBER(Edges[Relationship Date (UTC)])), Edges[Relationship Date (UTC)] >= Misc!$O$2), OR(NOT(ISNUMBER(Edges[Relationship Date (UTC)])), Edges[Relationship Date (UTC)] <= Misc!$P$2),OR(NOT(ISNUMBER(Edges[Tweet Date (UTC)])), Edges[Tweet Date (UTC)] >= Misc!$O$3), OR(NOT(ISNUMBER(Edges[Tweet Date (UTC)])), Edges[Tweet Date (UTC)] <= Misc!$P$3),TRUE), TRUE, FALSE) -> TRUE | O30: Mentions | P30: 43045.41 | Q30: RT @PlayStation_jp: 【PGW 2017】『コール オブ デューティ ワールドウォーII』ブースの対戦試遊をレポート！ 立体的で死角多数、マルチプレイヤー用追加マップ｢Carentan｣のスリリングな市街戦を体験！ https://t.co/RvyvhlLfi… | U30: 43045.41 | V30: https://twitter.com/#!/gouki21451224/status/927473392684429313 | Y30: 927473392684429313
A31: t_mogura42 | B31: eaa_tw | K31: No | L31: 31 | M31: =IF(AND(OR(NOT(ISNUMBER(Edges[Relationship Date (UTC)])), Edges[Relationship Date (UTC)] >= Misc!$O$2), OR(NOT(ISNUMBER(Edges[Relationship Date (UTC)])), Edges[Relationship Date (UTC)] <= Misc!$P$2),OR(NOT(ISNUMBER(Edges[Tweet Date (UTC)])), Edges[Tweet Date (UTC)] >= Misc!$O$3), OR(NOT(ISNUMBER(Edges[Tweet Date (UTC)])), Edges[Tweet Date (UTC)] <= Misc!$P$3),TRUE), TRUE, FALSE) -> TRUE | O31: Mentions | P31: 43045.41 | Q31: RT @EAA_tw: CoD:WWII： プレステージアイコン全10種と、プレステージマスターアイコンが判明 #CoDWWII https://t.co/PSkNgKtZ3K https://t.co/41SmfDFFhy | R31: http://fpsjp.net/archives/294392 | S31: fpsjp.net | T31: codwwii | U31: 43045.41 | V31: https://twitter.com/#!/t_mogura42/status/927473395230371840 | Y31: 927473395230371840
A32: introndepot | B32: game_collection | K32: No | L32: 32 | M32: =IF(AND(OR(NOT(ISNUMBER(Edges[Relationship Date (UTC)])), Edges[Relationship Date (UTC)] >= Misc!$O$2), OR(NOT(ISNUMBER(Edges[Relationship Date (UTC)])), Edges[Relationship Date (UTC)] <= Misc!$P$2),OR(NOT(ISNUMBER(Edges[Tweet Date (UTC)])), Edges[Tweet Date (UTC)] >= Misc!$O$3), OR(NOT(ISNUMBER(Edges[Tweet Date (UTC)])), Edges[Tweet Date (UTC)] <= Misc!$P$3),TRUE), TRUE, FALSE) -> TRUE | O32: Mentions | P32: 43045.411 | Q32: Win #CODWWII on #PS4 or #XboxOne! RT + Follow @postabargain &amp; @game_collection and enter here: https://t.co/x0IEyqkLVQ | R32: https://gleam.io/oyimv-f03kOk?l=http%3A%2F%2Fwww.postabargain.co.uk%2Fpages%2Fcompetition%2F2017%2Fcall-of-duty-wwii-giveaway | S32: gleam.io | T32: codwwii ps4 xboxone | U32: 43045.411 | V32: https://twitter.com/#!/introndepot/status/927473444689649665 | Y32: 927473444689649665
A33: introndepot | B33: postabargain | K33: No | L33: 33 | M33: =IF(AND(OR(NOT(ISNUMBER(Edges[Relationship Date (UTC)])), Edges[Relationship Date (UTC)] >= Misc!$O$2), OR(NOT(ISNUMBER(Edges[Relationship Date (UTC)])), Edges[Relationship Date (UTC)] <= Misc!$P$2),OR(NOT(ISNUMBER(Edges[Tweet Date (UTC)])), Edges[Tweet Date (UTC)] >= Misc!$O$3), OR(NOT(ISNUMBER(Edges[Tweet Date (UTC)])), Edges[Tweet Date (UTC)] <= Misc!$P$3),TRUE), TRUE, FALSE) -> TRUE | O33: Mentions | P33: 43045.411 | Q33: Win #CODWWII on #PS4 or #XboxOne! RT + Follow @postabargain &amp; @game_collection and enter here: https://t.co/x0IEyqkLVQ | R33: https://gleam.io/oyimv-f03kOk?l=http%3A%2F%2Fwww.postabargain.co.uk%2Fpages%2Fcompetition%2F2017%2Fcall-of-duty-wwii-giveaway | S33: gleam.io | T33: codwwii ps4 xboxone | U33: 43045.411 | V33: https://twitter.com/#!/introndepot/status/927473444689649665 | Y33: 927473444689649665
A34: shinobifist | B34: shinobifist | K34: No | L34: 34 | M34: =IF(AND(OR(NOT(ISNUMBER(Edges[Relationship Date (UTC)])), Edges[Relationship Date (UTC)] >= Misc!$O$2), OR(NOT(ISNUMBER(Edges[Relationship Date (UTC)])), Edges[Relationship Date (UTC)] <= Misc!$P$2),OR(NOT(ISNUMBER(Edges[Tweet Date (UTC)])), Edges[Tweet Date (UTC)] >= Misc!$O$3), OR(NOT(ISNUMBER(Edges[Tweet Date (UTC)])), Edges[Tweet Date (UTC)] <= Misc!$P$3),TRUE), TRUE, FALSE) -> TRUE | O34: Tweet | P34: 43045.411 | Q34: The BAR is so good in #CODWWII https://t.co/GcO7gtCJ2D | T34: codwwii | U34: 43045.411 | V34: https://twitter.com/#!/shinobifist/status/927473452008837121 | Y34: 927473452008837121
A35: vazquez151821 | B35: thegrefgyt | K35: No | L35: 35 | M35: =IF(AND(OR(NOT(ISNUMBER(Edges[Relationship Date (UTC)])), Edges[Relationship Date (UTC)] >= Misc!$O$2), OR(NOT(ISNUMBER(Edges[Relationship Date (UTC)])), Edges[Relationship Date (UTC)] <= Misc!$P$2),OR(NOT(ISNUMBER(Edges[Tweet Date (UTC)])), Edges[Tweet Date (UTC)] >= Misc!$O$3), OR(NOT(ISNUMBER(Edges[Tweet Date (UTC)])), Edges[Tweet Date (UTC)] <= Misc!$P$3),TRUE), TRUE, FALSE) -> TRUE | O35: Mentions | P35: 43045.411 | Q35: RT @TheGrefgYT: ¡NUEVO VÍDEO! 😡😠 #CODWWII ME BANEA 😠😡 RT Chicos!! 🙌🏻🔥▶️ https://t.co/78KdJQv8Ij https://t.co/heBObzc6N5 | R35: https://www.youtube.com/watch?v=-W5I1VoVWiI&feature=youtu.be | S35: youtube.com | T35: codwwii | U35: 43045.411 | V35: https://twitter.com/#!/vazquez151821/status/927473472837582848 | Y35: 927473472837582848
A36: eagle1928 | B36: eaa_tw | K36: No | L36: 36 | M36: =IF(AND(OR(NOT(ISNUMBER(Edges[Relationship Date (UTC)])), Edges[Relationship Date (UTC)] >= Misc!$O$2), OR(NOT(ISNUMBER(Edges[Relationship Date (UTC)])), Edges[Relationship Date (UTC)] <= Misc!$P$2),OR(NOT(ISNUMBER(Edges[Tweet Date (UTC)])), Edges[Tweet Date (UTC)] >= Misc!$O$3), OR(NOT(ISNUMBER(Edges[Tweet Date (UTC)])), Edges[Tweet Date (UTC)] <= Misc!$P$3),TRUE), TRUE, FALSE) -> TRUE | O36: Mentions | P36: 43045.411 | Q36: RT @EAA_tw: CoD:WWII：サーバーの接続問題や巻き戻し現象を修正！ 原因は予想以上の人気によるアクセス集中 #CoDWWII https://t.co/iMtnw5W2Tl https://t.co/VQkd1m6D3S | R36: http://fpsjp.net/archives/294374 | S36: fpsjp.net | T36: codwwii | U36: 43045.411 | V36: https://twitter.com/#!/eagle1928/status/927473494933327872 | Y36: 927473494933327872
A37: copper_kabell | B37: xboxodesperadoo | K37: No | L37: 37 | M37: =IF(AND(OR(NOT(ISNUMBER(Edges[Relationship Date (UTC)])), Edges[Relationship Date (UTC)] >= Misc!$O$2), OR(NOT(ISNUMBER(Edges[Relationship Date (UTC)])), Edges[Relationship Date (UTC)] <= Misc!$P$2),OR(NOT(ISNUMBER(Edges[Tweet Date (UTC)])), Edges[Tweet Date (UTC)] >= Misc!$O$3), OR(NOT(ISNUMBER(Edges[Tweet Date (UTC)])), Edges[Tweet Date (UTC)] <= Misc!$P$3),TRUE), TRUE, FALSE) -> TRUE | O37: Mentions | P37: 43045.411 | Q37: RT @WorldBestGaming: .@XBOXoDESPERADOo When someone tells you get to cover... you get to cover! 😂#CODWWII #WBGUP 👊 https://t.co/680eIBln6o | T37: codwwii wbgup | U37: 43045.411 | V37: https://twitter.com/#!/copper_kabell/status/927473503154163712 | Y37: 927473503154163712
A38: copper_kabell | B38: worldbestgaming | K38: No | L38: 38 | M38: =IF(AND(OR(NOT(ISNUMBER(Edges[Relationship Date (UTC)])), Edges[Relationship Date (UTC)] >= Misc!$O$2), OR(NOT(ISNUMBER(Edges[Relationship Date (UTC)])), Edges[Relationship Date (UTC)] <= Misc!$P$2),OR(NOT(ISNUMBER(Edges[Tweet Date (UTC)])), Edges[Tweet Date (UTC)] >= Misc!$O$3), OR(NOT(ISNUMBER(Edges[Tweet Date (UTC)])), Edges[Tweet Date (UTC)] <= Misc!$P$3),TRUE), TRUE, FALSE) -> TRUE | O38: Mentions | P38: 43045.411 | Q38: RT @WorldBestGaming: .@XBOXoDESPERADOo When someone tells you get to cover... you get to cover! 😂#CODWWII #WBGUP 👊 https://t.co/680eIBln6o | T38: codwwii wbgup | U38: 43045.411 | V38: https://twitter.com/#!/copper_kabell/status/927473503154163712 | Y38: 927473503154163712
A39: staceywwfc | B39: game_collection | K39: No | L39: 39 | M39: =IF(AND(OR(NOT(ISNUMBER(Edges[Relationship Date (UTC)])), Edges[Relationship Date (UTC)] >= Misc!$O$2), OR(NOT(ISNUMBER(Edges[Relationship Date (UTC)])), Edges[Relationship Date (UTC)] <= Misc!$P$2),OR(NOT(ISNUMBER(Edges[Tweet Date (UTC)])), Edges[Tweet Date (UTC)] >= Misc!$O$3), OR(NOT(ISNUMBER(Edges[Tweet Date (UTC)])), Edges[Tweet Date (UTC)] <= Misc!$P$3),TRUE), TRUE, FALSE) -> TRUE | O39: Mentions | P39: 43045.411 | Q39: Win #CODWWII on #PS4 or #XboxOne! RT + Follow @postabargain &amp; @game_collection and enter here: https://t.co/akDN6DztgC | R39: https://gleam.io/oyimv-0Xa1NB?l=http%3A%2F%2Fwww.postabargain.co.uk%2Fpages%2Fcompetition%2F2017%2Fcall-of-duty-wwii-giveaway | S39: gleam.io | T39: codwwii ps4 xboxone | U39: 43045.411 | V39: https://twitter.com/#!/staceywwfc/status/927473486695514112 | Y39: 927473486695514112
A40: staceywwfc | B40: postabargain | K40: No | L40: 40 | M40: =IF(AND(OR(NOT(ISNUMBER(Edges[Relationship Date (UTC)])), Edges[Relationship Date (UTC)] >= Misc!$O$2), OR(NOT(ISNUMBER(Edges[Relationship Date (UTC)])), Edges[Relationship Date (UTC)] <= Misc!$P$2),OR(NOT(ISNUMBER(Edges[Tweet Date (UTC)])), Edges[Tweet Date (UTC)] >= Misc!$O$3), OR(NOT(ISNUMBER(Edges[Tweet Date (UTC)])), Edges[Tweet Date (UTC)] <= Misc!$P$3),TRUE), TRUE, FALSE) -> TRUE | O40: Mentions | P40: 43045.411 | Q40: Win #CODWWII on #PS4 or #XboxOne! RT + Follow @postabargain &amp; @game_collection and enter here: https://t.co/akDN6DztgC | R40: https://gleam.io/oyimv-0Xa1NB?l=http%3A%2F%2Fwww.postabargain.co.uk%2Fpages%2Fcompetition%2F2017%2Fcall-of-duty-wwii-giveaway | S40: gleam.io | T40: codwwii ps4 xboxone | U40: 43045.411 | V40: https://twitter.com/#!/staceywwfc/status/927473486695514112 | Y40: 927473486695514112
...

Sheet Vertices
B1: Visual Properties | H1: Labels | L1: Layout | R1: Graph Metrics | AA1: Do Not Edit | AC1: Other Columns
A2: Vertex | B2: Color | C2: Shape | D2: Size | E2: Opacity | F2: Image File | G2: Visibility | H2: Label | I2: Label Fill Color | J2: Label Position | K2: Tooltip | L2: Layout Order | M2: X | N2: Y | O2: Locked? | P2: Polar R | Q2: Polar Angle | R2: Degree | S2: In-Degree | T2: Out-Degree | U2: Betweenness Centrality | V2: Closeness Centrality | W2: Eigenvector Centrality | X2: PageRank | Y2: Clustering Coefficient | Z2: Reciprocated Vertex Pair Ratio | AA2: ID | AB2: Dynamic Filter | AC2: Add Your Own Columns Here | AD2: Followed | AE2: Followers | AF2: Tweets | AG2: Favorites | AH2: Time Zone UTC Offset (Seconds) | AI2: Description | AJ2: Location | AK2: Web | AL2: Time Zone | AM2: Joined Twitter Date (UTC) | AN2: Custom Menu Item Text | AO2: Custom Menu Item Action | AP2: Tweeted Search Term? | AQ2: Top URLs in Tweet by Count | AR2: Top URLs in Tweet by Salience | AS2: Top Domains in Tweet by Count | AT2: Top Domains in Tweet by Salience | AU2: Top Hashtags in Tweet by Count | AV2: Top Hashtags in Tweet by Salience | AW2: Top Words in Tweet by Count | AX2: Top Words in Tweet by Salience | AY2: Top Word Pairs in Tweet by Count | AZ2: Top Word Pairs in Tweet by Salience
A3: cdiscount | B3: Red | C3: 11 | D3: 30 | E3: 100 | F3: http://pbs.twimg.com/profile_images/917402131652661249/DkoSj-wS_normal.jpg | K3: cdiscount | M3: 2580.7253 | N3: 3187.4128 | S3: 152 | T3: 0 | U3: 30105.7 | V3: 0.004545 | W3: 0.030709 | X3: 63.833625 | Y3: 0.00026141513 | Z3: 0 | AA3: 3 | AB3: =IF(AND(OR(NOT(ISNUMBER(Vertices[Size])), Vertices[Size] >= Misc!$O$4), OR(NOT(ISNUMBER(Vertices[Size])), Vertices[Size] <= Misc!$P$4),OR(NOT(ISNUMBER(Vertices[X])), Vertices[X] >= Misc!$O$5), OR(NOT(ISNUMBER(Vertices[X])), Vertices[X] <= Misc!$P$5),OR(NOT(ISNUMBER(Vertices[Y])), Vertices[Y] >= Misc!$O$6), OR(NOT(ISNUMBER(Vertices[Y])), Vertices[Y] <= Misc!$P$6),OR(NOT(ISNUMBER(Vertices[In-Degree])), Vertices[In-Degree] >= Misc!$O$7), OR(NOT(ISNUMBER(Vertices[In-Degree])), Vertices[In-Degree] <= Misc!$P$7),OR(NOT(ISNUMBER(Vertices[Out-Degree])), Vertices[Out-Degree] >= Misc!$O$8), OR(NOT(ISNUMBER(Vertices[Out-Degree])), Vertices[Out-Degree] <= Misc!$P$8),OR(NOT(ISNUMBER(Vertices[Betweenness Centrality])), Vertices[Betweenness Centrality] >= Misc!$O$9), OR(NOT(ISNUMBER(Vertices[Betweenness Centrality])), Vertices[Betweenness Centrality] <= Misc!$P$9),OR(NOT(ISNUMBER(Vertices[Closeness Centrality])), Vertices[Closeness Centrality] >= Misc!$O$10), OR(NOT(ISNUMBER(Vertices[Closeness Centrality])), Vertices[Closeness Centrality] <= Misc!$P$10),OR(NOT(ISNUMBER(Vertices[Eigenvector Centrality])), Vertices[Eigenvector Centrality] >= Misc!$O$11), OR(NOT(ISNUMBER(Vertices[Eigenvector Centrality])), Vertices[Eigenvector Centrality] <= Misc!$P$11),OR(NOT(ISNUMBER(Vertices[PageRank])), Vertices[PageRank] >= Misc!$O$12), OR(NOT(ISNUMBER(Vertices[PageRank])), Vertices[PageRank] <= Misc!$P$12),OR(NOT(ISNUMBER(Vertices[Clustering Coefficient])), Vertices[Clustering Coefficient] >= Misc!$O$13), OR(NOT(ISNUMBER(Vertices[Clustering Coefficient])), Vertices[Clustering Coefficient] <= Misc!$P$13),OR(NOT(ISNUMBER(Vertices[Reciprocated Vertex Pair Ratio])), Vertices[Reciprocated Vertex Pair Ratio] >= Misc!$O$14), OR(NOT(ISNUMBER(Vertices[Reciprocated Vertex Pair Ratio])), Vertices[Reciprocated Vertex Pair Ratio] <= Misc!$P$14),OR(NOT(ISNUMBER(Vertices[Followed])), Vertices[Followed] >= Misc!$O$15), OR(NOT(ISNUMBER(Vertices[Followed])), Vertices[Followed] <= Misc!$P$15),OR(NOT(ISNUMBER(Vertices[Followers])), Vertices[Followers] >= Misc!$O$16), OR(NOT(ISNUMBER(Vertices[Followers])), Vertices[Followers] <= Misc!$P$16),OR(NOT(ISNUMBER(Vertices[Tweets])), Vertices[Tweets] >= Misc!$O$17), OR(NOT(ISNUMBER(Vertices[Tweets])), Vertices[Tweets] <= Misc!$P$17),OR(NOT(ISNUMBER(Vertices[Favorites])), Vertices[Favorites] >= Misc!$O$18), OR(NOT(ISNUMBER(Vertices[Favorites])), Vertices[Favorites] <= Misc!$P$18),OR(NOT(ISNUMBER(Vertices[Time Zone UTC Offset (Seconds)])), Vertices[Time Zone UTC Offset (Seconds)] >= Misc!$O$19), OR(NOT(ISNUMBER(Vertices[Time Zone UTC Offset (Seconds)])), Vertices[Time Zone UTC Offset (Seconds)] <= Misc!$P$19),OR(NOT(ISNUMBER(Vertices[Joined Twitter Date (UTC)])), Vertices[Joined Twitter Date (UTC)] >= Misc!$O$20), OR(NOT(ISNUMBER(Vertices[Joined Twitter Date (UTC)])), Vertices[Joined Twitter Date (UTC)] <= Misc!$P$20),TRUE), TRUE, FALSE) -> FALSE | AD3: 3251 | AE3: 241562 | AF3: 71260 | AG3: 2072 | AH3: 3600 | AI3: Cdiscount, N'économisez pas votre plaisir ! #BonPlan & #Concours 👍 Besoin d'un conseil ? Nous sommes en DM de 08h à 19h | AJ3: France | AK3: https://t.co/IUhLib3sxX | AL3: Paris | AM3: 40030.592 | AN3: Open Twitter Page for This Person | AO3: https://twitter.com/cdiscount | AP3: No
A4: thegrefgyt | B4: Red | C4: 11 | D4: 30 | E4: 100 | F4: http://pbs.twimg.com/profile_images/902159333131264000/xZKRU8s3_normal.jpg | K4: thegrefgyt | M4: 1968.2689 | N4: 7743.728 | S4: 128 | T4: 0 | U4: 17018 | V4: 0.007463 | W4: 1e-06 | X4: 59.234589 | Y4: 0 | Z4: 0 | AA4: 4 | AB4: =IF(AND(OR(NOT(ISNUMBER(Vertices[Size])), Vertices[Size] >= Misc!$O$4), OR(NOT(ISNUMBER(Vertices[Size])), Vertices[Size] <= Misc!$P$4),OR(NOT(ISNUMBER(Vertices[X])), Vertices[X] >= Misc!$O$5), OR(NOT(ISNUMBER(Vertices[X])), Vertices[X] <= Misc!$P$5),OR(NOT(ISNUMBER(Vertices[Y])), Vertices[Y] >= Misc!$O$6), OR(NOT(ISNUMBER(Vertices[Y])), Vertices[Y] <= Misc!$P$6),OR(NOT(ISNUMBER(Vertices[In-Degree])), Vertices[In-Degree] >= Misc!$O$7), OR(NOT(ISNUMBER(Vertices[In-Degree])), Vertices[In-Degree] <= Misc!$P$7),OR(NOT(ISNUMBER(Vertices[Out-Degree])), Vertices[Out-Degree] >= Misc!$O$8), OR(NOT(ISNUMBER(Vertices[Out-Degree])), Vertices[Out-Degree] <= Misc!$P$8),OR(NOT(ISNUMBER(Vertices[Betweenness Centrality])), Vertices[Betweenness Centrality] >= Misc!$O$9), OR(NOT(ISNUMBER(Vertices[Betweenness Centrality])), Vertices[Betweenness Centrality] <= Misc!$P$9),OR(NOT(ISNUMBER(Vertices[Closeness Centrality])), Vertices[Closeness Centrality] >= Misc!$O$10), OR(NOT(ISNUMBER(Vertices[Closeness Centrality])), Vertices[Closeness Centrality] <= Misc!$P$10),OR(NOT(ISNUMBER(Vertices[Eigenvector Centrality])), Vertices[Eigenvector Centrality] >= Misc!$O$11), OR(NOT(ISNUMBER(Vertices[Eigenvector Centrality])), Vertices[Eigenvector Centrality] <= Misc!$P$11),OR(NOT(ISNUMBER(Vertices[PageRank])), Vertices[PageRank] >= Misc!$O$12), OR(NOT(ISNUMBER(Vertices[PageRank])), Vertices[PageRank] <= Misc!$P$12),OR(NOT(ISNUMBER(Vertices[Clustering Coefficient])), Vertices[Clustering Coefficient] >= Misc!$O$13), OR(NOT(ISNUMBER(Vertices[Clustering Coefficient])), Vertices[Clustering Coefficient] <= Misc!$P$13),OR(NOT(ISNUMBER(Vertices[Reciprocated Vertex Pair Ratio])), Vertices[Reciprocated Vertex Pair Ratio] >= Misc!$O$14), OR(NOT(ISNUMBER(Vertices[Reciprocated Vertex Pair Ratio])), Vertices[Reciprocated Vertex Pair Ratio] <= Misc!$P$14),OR(NOT(ISNUMBER(Vertices[Followed])), Vertices[Followed] >= Misc!$O$15), OR(NOT(ISNUMBER(Vertices[Followed])), Vertices[Followed] <= Misc!$P$15),OR(NOT(ISNUMBER(Vertices[Followers])), Vertices[Followers] >= Misc!$O$16), OR(NOT(ISNUMBER(Vertices[Followers])), Vertices[Followers] <= Misc!$P$16),OR(NOT(ISNUMBER(Vertices[Tweets])), Vertices[Tweets] >= Misc!$O$17), OR(NOT(ISNUMBER(Vertices[Tweets])), Vertices[Tweets] <= Misc!$P$17),OR(NOT(ISNUMBER(Vertices[Favorites])), Vertices[Favorites] >= Misc!$O$18), OR(NOT(ISNUMBER(Vertices[Favorites])), Vertices[Favorites] <= Misc!$P$18),OR(NOT(ISNUMBER(Vertices[Time Zone UTC Offset (Seconds)])), Vertices[Time Zone UTC Offset (Seconds)] >= Misc!$O$19), OR(NOT(ISNUMBER(Vertices[Time Zone UTC Offset (Seconds)])), Vertices[Time Zone UTC Offset (Seconds)] <= Misc!$P$19),OR(NOT(ISNUMBER(Vertices[Joined Twitter Date (UTC)])), Vertices[Joined Twitter Date (UTC)] >= Misc!$O$20), OR(NOT(ISNUMBER(Vertices[Joined Twitter Date (UTC)])), Vertices[Joined Twitter Date (UTC)] <= Misc!$P$20),TRUE), TRUE, FALSE) -> FALSE | AD4: 924 | AE4: 1332543 | AF4: 29088 | AG4: 33186 | AH4: 3600 | AI4: Do it! DO IT NOW! @TeamHeretics Owner. Business mail! contactothegrefg@gmail.com - https://t.co/cpNuKF7Woe | AJ4: Youtube Sky | AK4: http://t.co/Lvq0wNfyvT | AL4: Madrid | AM4: 41276.991 | AN4: Open Twitter Page for This Person | AO4: https://twitter.com/thegrefgyt | AP4: No
A5: codww2intel | B5: Red | C5: 11 | D5: 30 | E5: 100 | F5: http://pbs.twimg.com/profile_images/855475307213619200/8kh_qSBk_normal.jpg | K5: codww2intel | M5: 7457.2651 | N5: 2648.4304 | S5: 118 | T5: 0 | U5: 216972.42 | V5: 0.00034 | W5: 0 | X5: 51.635127 | Y5: 0 | Z5: 0 | AA5: 5 | AB5: =IF(AND(OR(NOT(ISNUMBER(Vertices[Size])), Vertices[Size] >= Misc!$O$4), OR(NOT(ISNUMBER(Vertices[Size])), Vertices[Size] <= Misc!$P$4),OR(NOT(ISNUMBER(Vertices[X])), Vertices[X] >= Misc!$O$5), OR(NOT(ISNUMBER(Vertices[X])), Vertices[X] <= Misc!$P$5),OR(NOT(ISNUMBER(Vertices[Y])), Vertices[Y] >= Misc!$O$6), OR(NOT(ISNUMBER(Vertices[Y])), Vertices[Y] <= Misc!$P$6),OR(NOT(ISNUMBER(Vertices[In-Degree])), Vertices[In-Degree] >= Misc!$O$7), OR(NOT(ISNUMBER(Vertices[In-Degree])), Vertices[In-Degree] <= Misc!$P$7),OR(NOT(ISNUMBER(Vertices[Out-Degree])), Vertices[Out-Degree] >= Misc!$O$8), OR(NOT(ISNUMBER(Vertices[Out-Degree])), Vertices[Out-Degree] <= Misc!$P$8),OR(NOT(ISNUMBER(Vertices[Betweenness Centrality])), Vertices[Betweenness Centrality] >= Misc!$O$9), OR(NOT(ISNUMBER(Vertices[Betweenness Centrality])), Vertices[Betweenness Centrality] <= Misc!$P$9),OR(NOT(ISNUMBER(Vertices[Closeness Centrality])), Vertices[Closeness Centrality] >= Misc!$O$10), OR(NOT(ISNUMBER(Vertices[Closeness Centrality])), Vertices[Closeness Centrality] <= Misc!$P$10),OR(NOT(ISNUMBER(Vertices[Eigenvector Centrality])), Vertices[Eigenvector Centrality] >= Misc!$O$11), OR(NOT(ISNUMBER(Vertices[Eigenvector Centrality])), Vertices[Eigenvector Centrality] <= Misc!$P$11),OR(NOT(ISNUMBER(Vertices[PageRank])), Vertices[PageRank] >= Misc!$O$12), OR(NOT(ISNUMBER(Vertices[PageRank])), Vertices[PageRank] <= Misc!$P$12),OR(NOT(ISNUMBER(Vertices[Clustering Coefficient])), Vertices[Clustering Coefficient] >= Misc!$O$13), OR(NOT(ISNUMBER(Vertices[Clustering Coefficient])), Vertices[Clustering Coefficient] <= Misc!$P$13),OR(NOT(ISNUMBER(Vertices[Reciprocated Vertex Pair Ratio])), Vertices[Reciprocated Vertex Pair Ratio] >= Misc!$O$14), OR(NOT(ISNUMBER(Vertices[Reciprocated Vertex Pair Ratio])), Vertices[Reciprocated Vertex Pair Ratio] <= Misc!$P$14),OR(NOT(ISNUMBER(Vertices[Followed])), Vertices[Followed] >= Misc!$O$15), OR(NOT(ISNUMBER(Vertices[Followed])), Vertices[Followed] <= Misc!$P$15),OR(NOT(ISNUMBER(Vertices[Followers])), Vertices[Followers] >= Misc!$O$16), OR(NOT(ISNUMBER(Vertices[Followers])), Vertices[Followers] <= Misc!$P$16),OR(NOT(ISNUMBER(Vertices[Tweets])), Vertices[Tweets] >= Misc!$O$17), OR(NOT(ISNUMBER(Vertices[Tweets])), Vertices[Tweets] <= Misc!$P$17),OR(NOT(ISNUMBER(Vertices[Favorites])), Vertices[Favorites] >= Misc!$O$18), OR(NOT(ISNUMBER(Vertices[Favorites])), Vertices[Favorites] <= Misc!$P$18),OR(NOT(ISNUMBER(Vertices[Time Zone UTC Offset (Seconds)])), Vertices[Time Zone UTC Offset (Seconds)] >= Misc!$O$19), OR(NOT(ISNUMBER(Vertices[Time Zone UTC Offset (Seconds)])), Vertices[Time Zone UTC Offset (Seconds)] <= Misc!$P$19),OR(NOT(ISNUMBER(Vertices[Joined Twitter Date (UTC)])), Vertices[Joined Twitter Date (UTC)] >= Misc!$O$20), OR(NOT(ISNUMBER(Vertices[Joined Twitter Date (UTC)])), Vertices[Joined Twitter Date (UTC)] <= Misc!$P$20),TRUE), TRUE, FALSE) -> FALSE | AD5: 360 | AE5: 157477 | AF5: 4684 | AG5: 26245 | AH5: 0 | AI5: Call of Duty WWII PC, Xbox One & PS4 Servers Down Status #CoDWWII #CoDWW2 Zombies #WWIIZombies #CallofDutyWWII #CallofDutyWW2 #CWL2018 - Run by @GamingIntelCom | AJ5: Los Angeles & London | AK5: https://t.co/nelJ9oWXfX | AL5: London | AM5: 41276.757 | AN5: Open Twitter Page for This Person | AO5: https://twitter.com/codww2intel | AP5: No
A6: eaa_tw | B6: Red | C6: 11 | D6: 30 | E6: 100 | F6: http://pbs.twimg.com/profile_images/770905568223506434/-Jcb2OZH_normal.jpg | K6: eaa_tw | M6: 3317.3066 | N6: 8128.1572 | S6: 93 | T6: 0 | U6: 8924 | V6: 0.010204 | W6: 0 | X6: 43.159427 | Y6: 0 | Z6: 0 | AA6: 6 | AB6: =IF(AND(OR(NOT(ISNUMBER(Vertices[Size])), Vertices[Size] >= Misc!$O$4), OR(NOT(ISNUMBER(Vertices[Size])), Vertices[Size] <= Misc!$P$4),OR(NOT(ISNUMBER(Vertices[X])), Vertices[X] >= Misc!$O$5), OR(NOT(ISNUMBER(Vertices[X])), Vertices[X] <= Misc!$P$5),OR(NOT(ISNUMBER(Vertices[Y])), Vertices[Y] >= Misc!$O$6), OR(NOT(ISNUMBER(Vertices[Y])), Vertices[Y] <= Misc!$P$6),OR(NOT(ISNUMBER(Vertices[In-Degree])), Vertices[In-Degree] >= Misc!$O$7), OR(NOT(ISNUMBER(Vertices[In-Degree])), Vertices[In-Degree] <= Misc!$P$7),OR(NOT(ISNUMBER(Vertices[Out-Degree])), Vertices[Out-Degree] >= Misc!$O$8), OR(NOT(ISNUMBER(Vertices[Out-Degree])), Vertices[Out-Degree] <= Misc!$P$8),OR(NOT(ISNUMBER(Vertices[Betweenness Centrality])), Vertices[Betweenness Centrality] >= Misc!$O$9), OR(NOT(ISNUMBER(Vertices[Betweenness Centrality])), Vertices[Betweenness Centrality] <= Misc!$P$9),OR(NOT(ISNUMBER(Vertices[Closeness Centrality])), Vertices[Closeness Centrality] >= Misc!$O$10), OR(NOT(ISNUMBER(Vertices[Closeness Centrality])), Vertices[Closeness Centrality] <= Misc!$P$10),OR(NOT(ISNUMBER(Vertices[Eigenvector Centrality])), Vertices[Eigenvector Centrality] >= Misc!$O$11), OR(NOT(ISNUMBER(Vertices[Eigenvector Centrality])), Vertices[Eigenvector Centrality] <= Misc!$P$11),OR(NOT(ISNUMBER(Vertices[PageRank])), Vertices[PageRank] >= Misc!$O$12), OR(NOT(ISNUMBER(Vertices[PageRank])), Vertices[PageRank] <= Misc!$P$12),OR(NOT(ISNUMBER(Vertices[Clustering Coefficient])), Vertices[Clustering Coefficient] >= Misc!$O$13), OR(NOT(ISNUMBER(Vertices[Clustering Coefficient])), Vertices[Clustering Coefficient] <= Misc!$P$13),OR(NOT(ISNUMBER(Vertices[Reciprocated Vertex Pair Ratio])), Vertices[Reciprocated Vertex Pair Ratio] >= Misc!$O$14), OR(NOT(ISNUMBER(Vertices[Reciprocated Vertex Pair Ratio])), Vertices[Reciprocated Vertex Pair Ratio] <= Misc!$P$14),OR(NOT(ISNUMBER(Vertices[Followed])), Vertices[Followed] >= Misc!$O$15), OR(NOT(ISNUMBER(Vertices[Followed])), Vertices[Followed] <= Misc!$P$15),OR(NOT(ISNUMBER(Vertices[Followers])), Vertices[Followers] >= Misc!$O$16), OR(NOT(ISNUMBER(Vertices[Followers])), Vertices[Followers] <= Misc!$P$16),OR(NOT(ISNUMBER(Vertices[Tweets])), Vertices[Tweets] >= Misc!$O$17), OR(NOT(ISNUMBER(Vertices[Tweets])), Vertices[Tweets] <= Misc!$P$17),OR(NOT(ISNUMBER(Vertices[Favorites])), Vertices[Favorites] >= Misc!$O$18), OR(NOT(ISNUMBER(Vertices[Favorites])), Vertices[Favorites] <= Misc!$P$18),OR(NOT(ISNUMBER(Vertices[Time Zone UTC Offset (Seconds)])), Vertices[Time Zone UTC Offset (Seconds)] >= Misc!$O$19), OR(NOT(ISNUMBER(Vertices[Time Zone UTC Offset (Seconds)])), Vertices[Time Zone UTC Offset (Seconds)] <= Misc!$P$19),OR(NOT(ISNUMBER(Vertices[Joined Twitter Date (UTC)])), Vertices[Joined Twitter Date (UTC)] >= Misc!$O$20), OR(NOT(ISNUMBER(Vertices[Joined Twitter Date (UTC)])), Vertices[Joined Twitter Date (UTC)] <= Misc!$P$20),TRUE), TRUE, FALSE) -> FALSE | AD6: 643 | AE6: 106912 | AF6: 16905 | AG6: 3775 | AH6: 32400 | AI6: FPS/TPSゲームサイト「EAA!!」の公式アカウントです。関係ない海外ニュースなどもノリで扱うよ。YouTube📺 https://t.co/yrnDgPUxNx / 中身@EAA_Nakami | AJ6: 最前線 | AK6: https://t.co/uDOuQQpBYL | AL6: Tokyo | AM6: 40866.974 | AN6: Open Twitter Page for This Person | AO6: https://twitter.com/eaa_tw | AP6: No
A7: hollowpoiint | B7: Red | C7: 11 | D7: 30 | E7: 100 | F7: http://pbs.twimg.com/profile_images/902532081116487680/JbMm17E__normal.jpg | K7: hollowpoiint | M7: 8655.2334 | N7: 4501.5869 | S7: 76 | T7: 0 | U7: 108400.55 | V7: 0.000361 | W7: 0 | X7: 33.677513 | Y7: 0 | Z7: 0 | AA7: 7 | AB7: =IF(AND(OR(NOT(ISNUMBER(Vertices[Size])), Vertices[Size] >= Misc!$O$4), OR(NOT(ISNUMBER(Vertices[Size])), Vertices[Size] <= Misc!$P$4),OR(NOT(ISNUMBER(Vertices[X])), Vertices[X] >= Misc!$O$5), OR(NOT(ISNUMBER(Vertices[X])), Vertices[X] <= Misc!$P$5),OR(NOT(ISNUMBER(Vertices[Y])), Vertices[Y] >= Misc!$O$6), OR(NOT(ISNUMBER(Vertices[Y])), Vertices[Y] <= Misc!$P$6),OR(NOT(ISNUMBER(Vertices[In-Degree])), Vertices[In-Degree] >= Misc!$O$7), OR(NOT(ISNUMBER(Vertices[In-Degree])), Vertices[In-Degree] <= Misc!$P$7),OR(NOT(ISNUMBER(Vertices[Out-Degree])), Vertices[Out-Degree] >= Misc!$O$8), OR(NOT(ISNUMBER(Vertices[Out-Degree])), Vertices[Out-Degree] <= Misc!$P$8),OR(NOT(ISNUMBER(Vertices[Betweenness Centrality])), Vertices[Betweenness Centrality] >= Misc!$O$9), OR(NOT(ISNUMBER(Vertices[Betweenness Centrality])), Vertices[Betweenness Centrality] <= Misc!$P$9),OR(NOT(ISNUMBER(Vertices[Closeness Centrality])), Vertices[Closeness Centrality] >= Misc!$O$10), OR(NOT(ISNUMBER(Vertices[Closeness Centrality])), Vertices[Closeness Centrality] <= Misc!$P$10),OR(NOT(ISNUMBER(Vertices[Eigenvector Centrality])), Vertices[Eigenvector Centrality] >= Misc!$O$11), OR(NOT(ISNUMBER(Vertices[Eigenvector Centrality])), Vertices[Eigenvector Centrality] <= Misc!$P$11),OR(NOT(ISNUMBER(Vertices[PageRank])), Vertices[PageRank] >= Misc!$O$12), OR(NOT(ISNUMBER(Vertices[PageRank])), Vertices[PageRank] <= Misc!$P$12),OR(NOT(ISNUMBER(Vertices[Clustering Coefficient])), Vertices[Clustering Coefficient] >= Misc!$O$13), OR(NOT(ISNUMBER(Vertices[Clustering Coefficient])), Vertices[Clustering Coefficient] <= Misc!$P$13),OR(NOT(ISNUMBER(Vertices[Reciprocated Vertex Pair Ratio])), Vertices[Reciprocated Vertex Pair Ratio] >= Misc!$O$14), OR(NOT(ISNUMBER(Vertices[Reciprocated Vertex Pair Ratio])), Vertices[Reciprocated Vertex Pair Ratio] <= Misc!$P$14),OR(NOT(ISNUMBER(Vertices[Followed])), Vertices[Followed] >= Misc!$O$15), OR(NOT(ISNUMBER(Vertices[Followed])), Vertices[Followed] <= Misc!$P$15),OR(NOT(ISNUMBER(Vertices[Followers])), Vertices[Followers] >= Misc!$O$16), OR(NOT(ISNUMBER(Vertices[Followers])), Vertices[Followers] <= Misc!$P$16),OR(NOT(ISNUMBER(Vertices[Tweets])), Vertices[Tweets] >= Misc!$O$17), OR(NOT(ISNUMBER(Vertices[Tweets])), Vertices[Tweets] <= Misc!$P$17),OR(NOT(ISNUMBER(Vertices[Favorites])), Vertices[Favorites] >= Misc!$O$18), OR(NOT(ISNUMBER(Vertices[Favorites])), Vertices[Favorites] <= Misc!$P$18),OR(NOT(ISNUMBER(Vertices[Time Zone UTC Offset (Seconds)])), Vertices[Time Zone UTC Offset (Seconds)] >= Misc!$O$19), OR(NOT(ISNUMBER(Vertices[Time Zone UTC Offset (Seconds)])), Vertices[Time Zone UTC Offset (Seconds)] <= Misc!$P$19),OR(NOT(ISNUMBER(Vertices[Joined Twitter Date (UTC)])), Vertices[Joined Twitter Date (UTC)] >= Misc!$O$20), OR(NOT(ISNUMBER(Vertices[Joined Twitter Date (UTC)])), Vertices[Joined Twitter Date (UTC)] <= Misc!$P$20),TRUE), TRUE, FALSE) -> FALSE | AD7: 488 | AE7: 134021 | AF7: 53254 | AG7: 46143 | AH7: -18000 | AI7: 1M+ Subscribers. Use Code HOLLOW For 10% OFF @Kontrolfreek @GFuelEnergy @scufgaming @astrogaming Business Inquiries: HollowPoiintBusiness@gmail.com | AK7: https://t.co/KnSAMYROfN | AL7: Eastern Time (US & Canada) | AM7: 41763.776 | AN7: Open Twitter Page for This Person | AO7: https://twitter.com/hollowpoiint | AP7: No
A8: callofduty | B8: Red | C8: 11 | D8: 30 | E8: 100 | F8: http://pbs.twimg.com/profile_images/911334549316972544/cHfFeiK6_normal.jpg | K8: callofduty | M8: 5244.1753 | N8: 8253.5957 | S8: 55 | T8: 0 | U8: 216519.92 | V8: 0.000377 | W8: 0 | X8: 15.307109 | Y8: 0.001010101 | Z8: 0 | AA8: 8 | AB8: =IF(AND(OR(NOT(ISNUMBER(Vertices[Size])), Vertices[Size] >= Misc!$O$4), OR(NOT(ISNUMBER(Vertices[Size])), Vertices[Size] <= Misc!$P$4),OR(NOT(ISNUMBER(Vertices[X])), Vertices[X] >= Misc!$O$5), OR(NOT(ISNUMBER(Vertices[X])), Vertices[X] <= Misc!$P$5),OR(NOT(ISNUMBER(Vertices[Y])), Vertices[Y] >= Misc!$O$6), OR(NOT(ISNUMBER(Vertices[Y])), Vertices[Y] <= Misc!$P$6),OR(NOT(ISNUMBER(Vertices[In-Degree])), Vertices[In-Degree] >= Misc!$O$7), OR(NOT(ISNUMBER(Vertices[In-Degree])), Vertices[In-Degree] <= Misc!$P$7),OR(NOT(ISNUMBER(Vertices[Out-Degree])), Vertices[Out-Degree] >= Misc!$O$8), OR(NOT(ISNUMBER(Vertices[Out-Degree])), Vertices[Out-Degree] <= Misc!$P$8),OR(NOT(ISNUMBER(Vertices[Betweenness Centrality])), Vertices[Betweenness Centrality] >= Misc!$O$9), OR(NOT(ISNUMBER(Vertices[Betweenness Centrality])), Vertices[Betweenness Centrality] <= Misc!$P$9),OR(NOT(ISNUMBER(Vertices[Closeness Centrality])), Vertices[Closeness Centrality] >= Misc!$O$10), OR(NOT(ISNUMBER(Vertices[Closeness Centrality])), Vertices[Closeness Centrality] <= Misc!$P$10),OR(NOT(ISNUMBER(Vertices[Eigenvector Centrality])), Vertices[Eigenvector Centrality] >= Misc!$O$11), OR(NOT(ISNUMBER(Vertices[Eigenvector Centrality])), Vertices[Eigenvector Centrality] <= Misc!$P$11),OR(NOT(ISNUMBER(Vertices[PageRank])), Vertices[PageRank] >= Misc!$O$12), OR(NOT(ISNUMBER(Vertices[PageRank])), Vertices[PageRank] <= Misc!$P$12),OR(NOT(ISNUMBER(Vertices[Clustering Coefficient])), Vertices[Clustering Coefficient] >= Misc!$O$13), OR(NOT(ISNUMBER(Vertices[Clustering Coefficient])), Vertices[Clustering Coefficient] <= Misc!$P$13),OR(NOT(ISNUMBER(Vertices[Reciprocated Vertex Pair Ratio])), Vertices[Reciprocated Vertex Pair Ratio] >= Misc!$O$14), OR(NOT(ISNUMBER(Vertices[Reciprocated Vertex Pair Ratio])), Vertices[Reciprocated Vertex Pair Ratio] <= Misc!$P$14),OR(NOT(ISNUMBER(Vertices[Followed])), Vertices[Followed] >= Misc!$O$15), OR(NOT(ISNUMBER(Vertices[Followed])), Vertices[Followed] <= Misc!$P$15),OR(NOT(ISNUMBER(Vertices[Followers])), Vertices[Followers] >= Misc!$O$16), OR(NOT(ISNUMBER(Vertices[Followers])), Vertices[Followers] <= Misc!$P$16),OR(NOT(ISNUMBER(Vertices[Tweets])), Vertices[Tweets] >= Misc!$O$17), OR(NOT(ISNUMBER(Vertices[Tweets])), Vertices[Tweets] <= Misc!$P$17),OR(NOT(ISNUMBER(Vertices[Favorites])), Vertices[Favorites] >= Misc!$O$18), OR(NOT(ISNUMBER(Vertices[Favorites])), Vertices[Favorites] <= Misc!$P$18),OR(NOT(ISNUMBER(Vertices[Time Zone UTC Offset (Seconds)])), Vertices[Time Zone UTC Offset (Seconds)] >= Misc!$O$19), OR(NOT(ISNUMBER(Vertices[Time Zone UTC Offset (Seconds)])), Vertices[Time Zone UTC Offset (Seconds)] <= Misc!$P$19),OR(NOT(ISNUMBER(Vertices[Joined Twitter Date (UTC)])), Vertices[Joined Twitter Date (UTC)] >= Misc!$O$20), OR(NOT(ISNUMBER(Vertices[Joined Twitter Date (UTC)])), Vertices[Joined Twitter Date (UTC)] <= Misc!$P$20),TRUE), TRUE, FALSE) -> FALSE | AD8: 11 | AE8: 3365814 | AF8: 16069 | AG8: 12188 | AH8: -28800 | AI8: Official Call of Duty® Twitter page. ESRB Rating: MATURE with Blood and Gore, Drug Reference, Intense Violence, Strong Language, and Suggestive Themes. | AK8: http://t.co/q8Cc0GQjNG | AL8: Pacific Time (US & Canada) | AM8: 40662.778 | AN8: Open Twitter Page for This Person | AO8: https://twitter.com/callofduty | AP8: No
A9: apex_clan1 | B9: Red | C9: 11 | D9: 30 | E9: 100 | F9: http://pbs.twimg.com/profile_images/912405397272764416/8FgyfvGo_normal.jpg | K9: apex_clan1 | M9: 9449.8496 | N9: 761.21246 | S9: 53 | T9: 0 | U9: 73908 | V9: 0.000243 | W9: 0 | X9: 24.267508 | Y9: 0 | Z9: 0 | AA9: 9 | AB9: =IF(AND(OR(NOT(ISNUMBER(Vertices[Size])), Vertices[Size] >= Misc!$O$4), OR(NOT(ISNUMBER(Vertices[Size])), Vertices[Size] <= Misc!$P$4),OR(NOT(ISNUMBER(Vertices[X])), Vertices[X] >= Misc!$O$5), OR(NOT(ISNUMBER(Vertices[X])), Vertices[X] <= Misc!$P$5),OR(NOT(ISNUMBER(Vertices[Y])), Vertices[Y] >= Misc!$O$6), OR(NOT(ISNUMBER(Vertices[Y])), Vertices[Y] <= Misc!$P$6),OR(NOT(ISNUMBER(Vertices[In-Degree])), Vertices[In-Degree] >= Misc!$O$7), OR(NOT(ISNUMBER(Vertices[In-Degree])), Vertices[In-Degree] <= Misc!$P$7),OR(NOT(ISNUMBER(Vertices[Out-Degree])), Vertices[Out-Degree] >= Misc!$O$8), OR(NOT(ISNUMBER(Vertices[Out-Degree])), Vertices[Out-Degree] <= Misc!$P$8),OR(NOT(ISNUMBER(Vertices[Betweenness Centrality])), Vertices[Betweenness Centrality] >= Misc!$O$9), OR(NOT(ISNUMBER(Vertices[Betweenness Centrality])), Vertices[Betweenness Centrality] <= Misc!$P$9),OR(NOT(ISNUMBER(Vertices[Closeness Centrality])), Vertices[Closeness Centrality] >= Misc!$O$10), OR(NOT(ISNUMBER(Vertices[Closeness Centrality])), Vertices[Closeness Centrality] <= Misc!$P$10),OR(NOT(ISNUMBER(Vertices[Eigenvector Centrality])), Vertices[Eigenvector Centrality] >= Misc!$O$11), OR(NOT(ISNUMBER(Vertices[Eigenvector Centrality])), Vertices[Eigenvector Centrality] <= Misc!$P$11),OR(NOT(ISNUMBER(Vertices[PageRank])), Vertices[PageRank] >= Misc!$O$12), OR(NOT(ISNUMBER(Vertices[PageRank])), Vertices[PageRank] <= Misc!$P$12),OR(NOT(ISNUMBER(Vertices[Clustering Coefficient])), Vertices[Clustering Coefficient] >= Misc!$O$13), OR(NOT(ISNUMBER(Vertices[Clustering Coefficient])), Vertices[Clustering Coefficient] <= Misc!$P$13),OR(NOT(ISNUMBER(Vertices[Reciprocated Vertex Pair Ratio])), Vertices[Reciprocated Vertex Pair Ratio] >= Misc!$O$14), OR(NOT(ISNUMBER(Vertices[Reciprocated Vertex Pair Ratio])), Vertices[Reciprocated Vertex Pair Ratio] <= Misc!$P$14),OR(NOT(ISNUMBER(Vertices[Followed])), Vertices[Followed] >= Misc!$O$15), OR(NOT(ISNUMBER(Vertices[Followed])), Vertices[Followed] <= Misc!$P$15),OR(NOT(ISNUMBER(Vertices[Followers])), Vertices[Followers] >= Misc!$O$16), OR(NOT(ISNUMBER(Vertices[Followers])), Vertices[Followers] <= Misc!$P$16),OR(NOT(ISNUMBER(Vertices[Tweets])), Vertices[Tweets] >= Misc!$O$17), OR(NOT(ISNUMBER(Vertices[Tweets])), Vertices[Tweets] <= Misc!$P$17),OR(NOT(ISNUMBER(Vertices[Favorites])), Vertices[Favorites] >= Misc!$O$18), OR(NOT(ISNUMBER(Vertices[Favorites])), Vertices[Favorites] <= Misc!$P$18),OR(NOT(ISNUMBER(Vertices[Time Zone UTC Offset (Seconds)])), Vertices[Time Zone UTC Offset (Seconds)] >= Misc!$O$19), OR(NOT(ISNUMBER(Vertices[Time Zone UTC Offset (Seconds)])), Vertices[Time Zone UTC Offset (Seconds)] <= Misc!$P$19),OR(NOT(ISNUMBER(Vertices[Joined Twitter Date (UTC)])), Vertices[Joined Twitter Date (UTC)] >= Misc!$O$20), OR(NOT(ISNUMBER(Vertices[Joined Twitter Date (UTC)])), Vertices[Joined Twitter Date (UTC)] <= Misc!$P$20),TRUE), TRUE, FALSE) -> FALSE | AD9: 56 | AE9: 31219 | AF9: 1486 | AG9: 529 | AH9: 3600 | AI9: Twitter officiel de la ApeX Clan. | AJ9: aymancontactpro@gmail.com | AK9: https://t.co/yFp8YBCfoc | AL9: Paris | AM9: 42142.979 | AN9: Open Twitter Page for This Person | AO9: https://twitter.com/apex_clan1 | AP9: No
